Workbook

Sheet Dashboards
B2: Volve Field Production Analysis (2008 - 2016)
B3: Equinor open dataset · Hugin Formation · water-injection waterflood
B4: Summary: Total Oil: 10.0M Sm³ · Peak Rate: ~9,000 Sm³/d · Field Life: 2008 - 2016 · Peak Water Cut: 97%

Sheet Well Summary
A1: Well | B1: Total Oil | C1: Peak Oil Rate | D1: Peak Water Cut | E1: Avg On-Stream Eff | F1: Role
A2: 15/9-F-12 | B2: =SUMIF('Clean Monthly Production Data '!$A$2:$A$527,'Well Summary'!A2,'Clean Monthly Production Data '!$G$2:$G$527) -> 4579609.5 | C2: =+_xlfn.MAXIFS('Clean Monthly Production Data '!$K$2:$K$527,'Clean Monthly Production Data '!$A$2:$A$527,'Well Summary'!A2) -> 5369.0216 | D2: =+_xlfn.MAXIFS('Clean Monthly Production Data '!$L$2:$L$527,'Clean Monthly Production Data '!$A$2:$A$527,A2) -> 0.96721935 | E2: =AVERAGEIFS('Clean Monthly Production Data '!$P$2:$P$527,'Clean Monthly Production Data '!$A$2:$A$527,'Well Summary'!A2) -> 0.87559167 | F2: =+IF(Table1[[#This Row],[Total Oil]]>0, "Producer",IF(SUMIF('Clean Monthly Production Data '!$A$2:$A$527,Table1[[#This Row],[Well]],'Clean Monthly Production Data '!$N$2:$N$527)>0,"Injector","No production")) -> Producer
A3: 15/9-F-14 | B3: =SUMIF('Clean Monthly Production Data '!$A$2:$A$527,'Well Summary'!A3,'Clean Monthly Production Data '!$G$2:$G$527) -> 3942233.4 | C3: =+_xlfn.MAXIFS('Clean Monthly Production Data '!$K$2:$K$527,'Clean Monthly Production Data '!$A$2:$A$527,'Well Summary'!A3) -> 4616.309 | D3: =+_xlfn.MAXIFS('Clean Monthly Production Data '!$L$2:$L$527,'Clean Monthly Production Data '!$A$2:$A$527,A3) -> 0.96725411 | E3: =AVERAGEIFS('Clean Monthly Production Data '!$P$2:$P$527,'Clean Monthly Production Data '!$A$2:$A$527,'Well Summary'!A3) -> 0.8862119 | F3: =+IF(Table1[[#This Row],[Total Oil]]>0, "Producer",IF(SUMIF('Clean Monthly Production Data '!$A$2:$A$527,Table1[[#This Row],[Well]],'Clean Monthly Production Data '!$N$2:$N$527)>0,"Injector","No production")) -> Producer
A4: 15/9-F-11 | B4: =SUMIF('Clean Monthly Production Data '!$A$2:$A$527,'Well Summary'!A4,'Clean Monthly Production Data '!$G$2:$G$527) -> 1147849.1 | C4: =+_xlfn.MAXIFS('Clean Monthly Production Data '!$K$2:$K$527,'Clean Monthly Production Data '!$A$2:$A$527,'Well Summary'!A4) -> 1818.5253 | D4: =+_xlfn.MAXIFS('Clean Monthly Production Data '!$L$2:$L$527,'Clean Monthly Production Data '!$A$2:$A$527,A4) -> 0.85750551 | E4: =AVERAGEIFS('Clean Monthly Production Data '!$P$2:$P$527,'Clean Monthly Production Data '!$A$2:$A$527,'Well Summary'!A4) -> 0.91216295 | F4: =+IF(Table1[[#This Row],[Total Oil]]>0, "Producer",IF(SUMIF('Clean Monthly Production Data '!$A$2:$A$527,Table1[[#This Row],[Well]],'Clean Monthly Production Data '!$N$2:$N$527)>0,"Injector","No production")) -> Producer
A5: 15/9-F-1 C | B5: =SUMIF('Clean Monthly Production Data '!$A$2:$A$527,'Well Summary'!A5,'Clean Monthly Production Data '!$G$2:$G$527) -> 177709.33 | C5: =+_xlfn.MAXIFS('Clean Monthly Production Data '!$K$2:$K$527,'Clean Monthly Production Data '!$A$2:$A$527,'Well Summary'!A5) -> 1175.4694 | D5: =+_xlfn.MAXIFS('Clean Monthly Production Data '!$L$2:$L$527,'Clean Monthly Production Data '!$A$2:$A$527,A5) -> 0.82480379 | E5: =AVERAGEIFS('Clean Monthly Production Data '!$P$2:$P$527,'Clean Monthly Production Data '!$A$2:$A$527,'Well Summary'!A5) -> 0.54769477 | F5: =+IF(Table1[[#This Row],[Total Oil]]>0, "Producer",IF(SUMIF('Clean Monthly Production Data '!$A$2:$A$527,Table1[[#This Row],[Well]],'Clean Monthly Production Data '!$N$2:$N$527)>0,"Injector","No production")) -> Producer
A6: 15/9-F-15 D | B6: =SUMIF('Clean Monthly Production Data '!$A$2:$A$527,'Well Summary'!A6,'Clean Monthly Production Data '!$G$2:$G$527) -> 148518.56 | C6: =+_xlfn.MAXIFS('Clean Monthly Production Data '!$K$2:$K$527,'Clean Monthly Production Data '!$A$2:$A$527,'Well Summary'!A6) -> 400.66031 | D6: =+_xlfn.MAXIFS('Clean Monthly Production Data '!$L$2:$L$527,'Clean Monthly Production Data '!$A$2:$A$527,A6) -> 0.60879268 | E6: =AVERAGEIFS('Clean Monthly Production Data '!$P$2:$P$527,'Clean Monthly Production Data '!$A$2:$A$527,'Well Summary'!A6) -> 0.8163346 | F6: =+IF(Table1[[#This Row],[Total Oil]]>0, "Producer",IF(SUMIF('Clean Monthly Production Data '!$A$2:$A$527,Table1[[#This Row],[Well]],'Clean Monthly Production Data '!$N$2:$N$527)>0,"Injector","No production")) -> Producer
A7: 15/9-F-5 | B7: =SUMIF('Clean Monthly Production Data '!$A$2:$A$527,'Well Summary'!A7,'Clean Monthly Production Data '!$G$2:$G$527) -> 41160.68 | C7: =+_xlfn.MAXIFS('Clean Monthly Production Data '!$K$2:$K$527,'Clean Monthly Production Data '!$A$2:$A$527,'Well Summary'!A7) -> 358.40865 | D7: =+_xlfn.MAXIFS('Clean Monthly Production Data '!$L$2:$L$527,'Clean Monthly Production Data '!$A$2:$A$527,A7) -> 0.41180062 | E7: =AVERAGEIFS('Clean Monthly Production Data '!$P$2:$P$527,'Clean Monthly Production Data '!$A$2:$A$527,'Well Summary'!A7) -> 0.85871215 | F7: =+IF(Table1[[#This Row],[Total Oil]]>0, "Producer",IF(SUMIF('Clean Monthly Production Data '!$A$2:$A$527,Table1[[#This Row],[Well]],'Clean Monthly Production Data '!$N$2:$N$527)>0,"Injector","No production")) -> Producer
A8: 15/9-F-4 | B8: =SUMIF('Clean Monthly Production Data '!$A$2:$A$527,'Well Summary'!A8,'Clean Monthly Production Data '!$G$2:$G$527) -> 0 | C8: =+_xlfn.MAXIFS('Clean Monthly Production Data '!$K$2:$K$527,'Clean Monthly Production Data '!$A$2:$A$527,'Well Summary'!A8) -> 0 | D8: =+_xlfn.MAXIFS('Clean Monthly Production Data '!$L$2:$L$527,'Clean Monthly Production Data '!$A$2:$A$527,A8) -> 0 | E8: =AVERAGEIFS('Clean Monthly Production Data '!$P$2:$P$527,'Clean Monthly Production Data '!$A$2:$A$527,'Well Summary'!A8) -> 0.8625894 | F8: =+IF(Table1[[#This Row],[Total Oil]]>0, "Producer",IF(SUMIF('Clean Monthly Production Data '!$A$2:$A$527,Table1[[#This Row],[Well]],'Clean Monthly Production Data '!$N$2:$N$527)>0,"Injector","No production")) -> Injector

Sheet Clean Monthly Production Data 
A1: Wellbore name | B1: NPD Code | C1: Year | D1: Month | E1: Date | F1: On Stream (hrs) | G1: Oil (Sm3) | H1: Gas (Sm3) | I1: Water (Sm3) | J1: Calc. Oil Rate (Sm3/day) | K1: Oil Rate (Sm3/d) | L1: Water Cut | M1: GI (Sm3) | N1: WI (Sm3) | O1: Well Role | P1: On-Stream Eff
A2: 15/9-F-1 C | B2: 7405 | C2: 2014 | D2: 4 | E2: =DATE(C2, D2, 1) -> 41730 | F2: 227.5 | G2: 11142.47 | H2: 1597936.6 | I2: 0 | J2: =IF(F2>0,G2/(F2/24),"") -> 1175.4694 | K2: =+J2 -> 1175.4694 | L2: =+IF((G2+I2)>0,I2/(G2+I2),"") -> 0 | M2: 0 | N2: 0 | O2: =IF(F2>0,IF(N(N2)>0,"Injector",IF(N(G2)>0,"Producer","Inactive")),"No production") -> Producer | P2: =+IF(F2>0,F2/(DAY(EOMONTH(E2,0))*24),"") -> 0.31597222
A3: 15/9-F-1 C | B3: 7405 | C3: 2014 | D3: 5 | E3: =DATE(C3, D3, 1) -> 41760 | F3: 733.83334 | G3: 24901.95 | H3: 3496229.6 | I3: 783.48 | J3: =IF(F3>0,G3/(F3/24),"") -> 814.41762 | K3: =+J3 -> 814.41762 | L3: =+IF((G3+I3)>0,I3/(G3+I3),"") -> 0.030502896 | M3: 0 | N3: 0 | O3: =IF(F3>0,IF(N(N3)>0,"Injector",IF(N(G3)>0,"Producer","Inactive")),"No production") -> Producer | P3: =+IF(F3>0,F3/(DAY(EOMONTH(E3,0))*24),"") -> 0.98633513
A4: 15/9-F-1 C | B4: 7405 | C4: 2014 | D4: 6 | E4: =DATE(C4, D4, 1) -> 41791 | F4: 705.91666 | G4: 19617.76 | H4: 2886661.7 | I4: 2068.48 | J4: =IF(F4>0,G4/(F4/24),"") -> 666.97142 | K4: =+J4 -> 666.97142 | L4: =+IF((G4+I4)>0,I4/(G4+I4),"") -> 0.095382141 | M4: 0 | N4: 0 | O4: =IF(F4>0,IF(N(N4)>0,"Injector",IF(N(G4)>0,"Producer","Inactive")),"No production") -> Producer | P4: =+IF(F4>0,F4/(DAY(EOMONTH(E4,0))*24),"") -> 0.98043981
A5: 15/9-F-1 C | B5: 7405 | C5: 2014 | D5: 7 | E5: =DATE(C5, D5, 1) -> 41821 | F5: 742.41666 | G5: 15085.68 | H5: 2249365.8 | I5: 6243.98 | J5: =IF(F5>0,G5/(F5/24),"") -> 487.67268 | K5: =+J5 -> 487.67268 | L5: =+IF((G5+I5)>0,I5/(G5+I5),"") -> 0.29273697 | M5: 0 | N5: 0 | O5: =IF(F5>0,IF(N(N5)>0,"Injector",IF(N(G5)>0,"Producer","Inactive")),"No production") -> Producer | P5: =+IF(F5>0,F5/(DAY(EOMONTH(E5,0))*24),"") -> 0.99787185
A6: 15/9-F-1 C | B6: 7405 | C6: 2014 | D6: 8 | E6: =DATE(C6, D6, 1) -> 41852 | F6: 432.99166 | G6: 6970.43 | H6: 1048190.8 | I6: 4529.75 | J6: =IF(F6>0,G6/(F6/24),"") -> 386.35922 | K6: =+J6 -> 386.35922 | L6: =+IF((G6+I6)>0,I6/(G6+I6),"") -> 0.39388514 | M6: 0 | N6: 0 | O6: =IF(F6>0,IF(N(N6)>0,"Injector",IF(N(G6)>0,"Producer","Inactive")),"No production") -> Producer | P6: =+IF(F6>0,F6/(DAY(EOMONTH(E6,0))*24),"") -> 0.58197804
A7: 15/9-F-1 C | B7: 7405 | C7: 2014 | D7: 9 | E7: =DATE(C7, D7, 1) -> 41883 | F7: 630.3 | G7: 9168.43 | H7: 1414100 | I7: 8317.59 | J7: =IF(F7>0,G7/(F7/24),"") -> 349.10728 | K7: =+J7 -> 349.10728 | L7: =+IF((G7+I7)>0,I7/(G7+I7),"") -> 0.47567085 | M7: 0 | N7: 0 | O7: =IF(F7>0,IF(N(N7)>0,"Injector",IF(N(G7)>0,"Producer","Inactive")),"No production") -> Producer | P7: =+IF(F7>0,F7/(DAY(EOMONTH(E7,0))*24),"") -> 0.87541667
A8: 15/9-F-1 C | B8: 7405 | C8: 2014 | D8: 10 | E8: =DATE(C8, D8, 1) -> 41913 | F8: 745 | G8: 9468.06 | H8: 1462064 | I8: 10364.87 | J8: =IF(F8>0,G8/(F8/24),"") -> 305.01133 | K8: =+J8 -> 305.01133 | L8: =+IF((G8+I8)>0,I8/(G8+I8),"") -> 0.52260912 | M8: 0 | N8: 0 | O8: =IF(F8>0,IF(N(N8)>0,"Injector",IF(N(G8)>0,"Producer","Inactive")),"No production") -> Producer | P8: =+IF(F8>0,F8/(DAY(EOMONTH(E8,0))*24),"") -> 1.0013441
A9: 15/9-F-1 C | B9: 7405 | C9: 2014 | D9: 11 | E9: =DATE(C9, D9, 1) -> 41944 | F9: 579.775 | G9: 6710.33 | H9: 1044188.3 | I9: 7234.24 | J9: =IF(F9>0,G9/(F9/24),"") -> 277.77659 | K9: =+J9 -> 277.77659 | L9: =+IF((G9+I9)>0,I9/(G9+I9),"") -> 0.51878545 | M9: 0 | N9: 0 | O9: =IF(F9>0,IF(N(N9)>0,"Injector",IF(N(G9)>0,"Producer","Inactive")),"No production") -> Producer | P9: =+IF(F9>0,F9/(DAY(EOMONTH(E9,0))*24),"") -> 0.80524306
A10: 15/9-F-1 C | B10: 7405 | C10: 2014 | D10: 12 | E10: =DATE(C10, D10, 1) -> 41974 | F10: 27.5 | G10: 120.29 | H10: 25857.08 | I10: 183.44 | J10: =IF(F10>0,G10/(F10/24),"") -> 104.98036 | K10: =+J10 -> 104.98036 | L10: =+IF((G10+I10)>0,I10/(G10+I10),"") -> 0.60395746 | M10: 0 | N10: 0 | O10: =IF(F10>0,IF(N(N10)>0,"Injector",IF(N(G10)>0,"Producer","Inactive")),"No production") -> Producer | P10: =+IF(F10>0,F10/(DAY(EOMONTH(E10,0))*24),"") -> 0.036962366
A11: 15/9-F-1 C | B11: 7405 | C11: 2015 | D11: 1 | E11: =DATE(C11, D11, 1) -> 42005 | F11: 479.91667 | G11: 10875.53 | H11: 1604934.6 | I11: 6850.8 | J11: =IF(F11>0,G11/(F11/24),"") -> 543.87092 | K11: =+J11 -> 543.87092 | L11: =+IF((G11+I11)>0,I11/(G11+I11),"") -> 0.38647594 | M11: 0 | N11: 0 | O11: =IF(F11>0,IF(N(N11)>0,"Injector",IF(N(G11)>0,"Producer","Inactive")),"No production") -> Producer | P11: =+IF(F11>0,F11/(DAY(EOMONTH(E11,0))*24),"") -> 0.64504929
A12: 15/9-F-1 C | B12: 7405 | C12: 2015 | D12: 2 | E12: =DATE(C12, D12, 1) -> 42036 | F12: 437.41667 | G12: 9586.64 | H12: 1439453.7 | I12: 10744.99 | J12: =IF(F12>0,G12/(F12/24),"") -> 525.99587 | K12: =+J12 -> 525.99587 | L12: =+IF((G12+I12)>0,I12/(G12+I12),"") -> 0.5284864 | M12: 0 | N12: 0 | O12: =IF(F12>0,IF(N(N12)>0,"Injector",IF(N(G12)>0,"Producer","Inactive")),"No production") -> Producer | P12: =+IF(F12>0,F12/(DAY(EOMONTH(E12,0))*24),"") -> 0.65091766
A13: 15/9-F-1 C | B13: 7405 | C13: 2015 | D13: 3 | E13: =DATE(C13, D13, 1) -> 42064 | F13: 320.20833 | G13: 5879.22 | H13: 856681.45 | I13: 11607.44 | J13: =IF(F13>0,G13/(F13/24),"") -> 440.65462 | K13: =+J13 -> 440.65462 | L13: =+IF((G13+I13)>0,I13/(G13+I13),"") -> 0.66378828 | M13: 0 | N13: 0 | O13: =IF(F13>0,IF(N(N13)>0,"Injector",IF(N(G13)>0,"Producer","Inactive")),"No production") -> Producer | P13: =+IF(F13>0,F13/(DAY(EOMONTH(E13,0))*24),"") -> 0.43038754
... A527: 15/9-F-5 | B527: 5769 | C527: 2016 | D527: 9 | E527: =DATE(C527, D527, 1) -> 42614 | F527: 0 | G527: 0 | H527: 0 | I527: 0 | J527: =IF(F527>0,G527/(F527/24),"") | K527: =+J527 | L527: =+IF((G527+I527)>0,I527/(G527+I527),"") | M527: 0 | N527: 0 | O527: =IF(F527>0,IF(N(N527)>0,"Injector",IF(N(G527)>0,"Producer","Inactive")),"No production") -> No production | P527: =+IF(F527>0,F527/(DAY(EOMONTH(E527,0))*24),"")

Sheet Monthly Pivot
A2: Row Labels | B2: Sum of Oil (Sm3)
A3: 15/9-F-12 | B3: 4579609.5
A4: 15/9-F-14 | B4: 3942233.4
A5: 15/9-F-11 | B5: 1147849.1
A6: 15/9-F-1 C | B6: 177709.33
A7: 15/9-F-15 D | B7: 148518.56
A8: 15/9-F-5 | B8: 41160.68
A9: 15/9-F-4 | B9: 0
A10: Grand Total | B10: 10037081
A29: Well Role | B29: Producer
A31: Sum of Oil (Sm3) | B31: Column Labels
A32: Row Labels | B32: 15/9-F-1 C | C32: 15/9-F-11 | D32: 15/9-F-12 | E32: 15/9-F-14 | F32: 15/9-F-15 D | G32: 15/9-F-5 | H32: Grand Total
A33: 2008 | D33: 1173446.7 | E33: 590928.49 | H33: 1764375.1
A34: Feb | D34: 49091.06 | H34: 49091.06
A35: Mar | D35: 83361.26 | H35: 83361.26
A36: Apr | D36: 74532.45 | H36: 74532.45
A37: May | D37: 125478.56 | H37: 125478.56
A38: Jun | D38: 143786.85 | H38: 143786.85
A39: Jul | D39: 114994.61 | E39: 51285.08 | H39: 166279.69
A40: Aug | D40: 97822.46 | E40: 67621.2 | H40: 165443.66
A41: Sept | D41: 77666.95 | E41: 114596.26 | H41: 192263.21
A42: Oct | D42: 94357.23 | E42: 142817.06 | H42: 237174.29
A43: Nov | D43: 145915.56 | E43: 104409.61 | H43: 250325.17
A44: Dec | D44: 166439.67 | E44: 110199.28 | H44: 276638.95
A45: 2009 | D45: 1522540.5 | E45: 1161851.5 | H45: 2684392
A46: Jan | D46: 153677.16 | E46: 115572.66 | H46: 269249.82
A47: Feb | D47: 121905.01 | E47: 113880.98 | H47: 235785.99
A48: Mar | D48: 92958.71 | E48: 90644.44 | H48: 183603.15
A49: Apr | D49: 150955.68 | E49: 86944.06 | H49: 237899.74
A50: May | D50: 141039.01 | E50: 116175.04 | H50: 257214.05
... A96: Dec | D96: 16320.65 | E96: 30122.89 | H96: 46443.54
A97: 2013 | C97: 156100.83 | D97: 138153.5 | E97: 263758.2 | H97: 558012.53
A98: Jan | D98: 17408.57 | E98: 30184.8 | H98: 47593.37
A99: Feb | D99: 15087.38 | E99: 26595.53 | H99: 41682.91
A100: Mar | D100: 6305.81 | E100: 18816.52 | H100: 25122.33
A101: Apr | D101: 12351.34 | E101: 22875.42 | H101: 35226.76
A102: May | D102: 16313.4 | E102: 27661.53 | H102: 43974.93
A103: Jun | D103: 11899.57 | E103: 22298.26 | H103: 34197.83
A104: Jul | C104: 3923.08 | D104: 11861.63 | E104: 22602.78 | H104: 38387.49
A105: Aug | C105: 25496.07 | D105: 15147.18 | E105: 21666.9 | H105: 62310.15
...

Sheet Raw Monthly Production Data
A1: Wellbore name | B1: NPDCode | C1: Year | D1: Month | E1: On Stream | F1: Oil | G1: Gas | H1: Water | I1: GI | J1: WI | K1: Role
E2: hrs | F2: Sm3 | G2: Sm3 | H2: Sm3 | I2: Sm3 | J2: Sm3
A3: 15/9-F-1 C | B3: 7405 | C3: 2014 | D3: 4 | E3: 227.5 | F3: 11142.47 | G3: 1597936.6 | H3: 0 | I3: NULL | J3: NULL
A4: 15/9-F-1 C | B4: 7405 | C4: 2014 | D4: 5 | E4: 733.83334 | F4: 24901.95 | G4: 3496229.6 | H4: 783.48 | I4: NULL | J4: NULL
A5: 15/9-F-1 C | B5: 7405 | C5: 2014 | D5: 6 | E5: 705.91666 | F5: 19617.76 | G5: 2886661.7 | H5: 2068.48 | I5: NULL | J5: NULL
A6: 15/9-F-1 C | B6: 7405 | C6: 2014 | D6: 7 | E6: 742.41666 | F6: 15085.68 | G6: 2249365.8 | H6: 6243.98 | I6: NULL | J6: NULL
A7: 15/9-F-1 C | B7: 7405 | C7: 2014 | D7: 8 | E7: 432.99166 | F7: 6970.43 | G7: 1048190.8 | H7: 4529.75 | I7: NULL | J7: NULL
A8: 15/9-F-1 C | B8: 7405 | C8: 2014 | D8: 9 | E8: 630.3 | F8: 9168.43 | G8: 1414100 | H8: 8317.59 | I8: NULL | J8: NULL
A9: 15/9-F-1 C | B9: 7405 | C9: 2014 | D9: 10 | E9: 745 | F9: 9468.06 | G9: 1462064 | H9: 10364.87 | I9: NULL | J9: NULL
A10: 15/9-F-1 C | B10: 7405 | C10: 2014 | D10: 11 | E10: 579.775 | F10: 6710.33 | G10: 1044188.3 | H10: 7234.24 | I10: NULL | J10: NULL
A11: 15/9-F-1 C | B11: 7405 | C11: 2014 | D11: 12 | E11: 27.5 | F11: 120.29 | G11: 25857.08 | H11: 183.44 | I11: NULL | J11: NULL
A12: 15/9-F-1 C | B12: 7405 | C12: 2015 | D12: 1 | E12: 479.91667 | F12: 10875.53 | G12: 1604934.6 | H12: 6850.8 | I12: NULL | J12: NULL
A13: 15/9-F-1 C | B13: 7405 | C13: 2015 | D13: 2 | E13: 437.41667 | F13: 9586.64 | G13: 1439453.7 | H13: 10744.99 | I13: NULL | J13: NULL
A14: 15/9-F-1 C | B14: 7405 | C14: 2015 | D14: 3 | E14: 320.20833 | F14: 5879.22 | G14: 856681.45 | H14: 11607.44 | I14: NULL | J14: NULL
... A307: 15/9-F-15 D | B307: 7289 | C307: 2016 | D307: 9 | E307: 0 | F307: 0 | G307: 0 | H307: 0 | I307: NULL | J307: NULL
A308: 15/9-F-4 | B308: 5693 | C308: 2007 | D308: 9 | E308: NULL | F308: NULL | G308: NULL | H308: NULL | I308: NULL | J308: NULL
A309: 15/9-F-4 | B309: 5693 | C309: 2007 | D309: 10 | E309: NULL | F309: NULL | G309: NULL | H309: NULL | I309: NULL | J309: NULL
A310: 15/9-F-4 | B310: 5693 | C310: 2007 | D310: 11 | E310: NULL | F310: NULL | G310: NULL | H310: NULL | I310: NULL | J310: NULL
A311: 15/9-F-4 | B311: 5693 | C311: 2007 | D311: 12 | E311: NULL | F311: NULL | G311: NULL | H311: NULL | I311: NULL | J311: NULL
A312: 15/9-F-4 | B312: 5693 | C312: 2008 | D312: 1 | E312: 0 | F312: NULL | G312: NULL | H312: NULL | I312: NULL | J312: NULL
A313: 15/9-F-4 | B313: 5693 | C313: 2008 | D313: 2 | E313: 0 | F313: NULL | G313: NULL | H313: NULL | I313: NULL | J313: NULL
A314: 15/9-F-4 | B314: 5693 | C314: 2008 | D314: 3 | E314: 0 | F314: NULL | G314: NULL | H314: NULL | I314: NULL | J314: 0
A315: 15/9-F-4 | B315: 5693 | C315: 2008 | D315: 4 | E315: 118.65 | F315: NULL | G315: NULL | H315: NULL | I315: NULL | J315: 29752.687
A316: 15/9-F-4 | B316: 5693 | C316: 2008 | D316: 5 | E316: 714.005 | F316: NULL | G316: NULL | H316: NULL | I316: NULL | J316: 221337.11
A317: 15/9-F-4 | B317: 5693 | C317: 2008 | D317: 6 | E317: 598.81667 | F317: NULL | G317: NULL | H317: NULL | I317: NULL | J317: 211803.65
A318: 15/9-F-4 | B318: 5693 | C318: 2008 | D318: 7 | E318: 620.80833 | F318: NULL | G318: NULL | H318: NULL | I318: NULL | J318: 232029.66
A319: 15/9-F-4 | B319: 5693 | C319: 2008 | D319: 8 | E319: 663.07502 | F319: NULL | G319: NULL | H319: NULL | I319: NULL | J319: 213913.26
A320: 15/9-F-4 | B320: 5693 | C320: 2008 | D320: 9 | E320: 558.14562 | F320: NULL | G320: NULL | H320: NULL | I320: NULL | J320: 98583.301
A321: 15/9-F-4 | B321: 5693 | C321: 2008 | D321: 10 | E321: 701.91667 | F321: NULL | G321: NULL | H321: NULL | I321: NULL | J321: 233503.41
A322: 15/9-F-4 | B322: 5693 | C322: 2008 | D322: 11 | E322: 711.66667 | F322: NULL | G322: NULL | H322: NULL | I322: NULL | J322: 222126.1
A323: 15/9-F-4 | B323: 5693 | C323: 2008 | D323: 12 | E323: 742.66666 | F323: NULL | G323: NULL | H323: NULL | I323: NULL | J323: 263191.84
A324: 15/9-F-4 | B324: 5693 | C324: 2009 | D324: 1 | E324: 699.33332 | F324: NULL | G324: NULL | H324: NULL | I324: NULL | J324: 246659.9
A325: 15/9-F-4 | B325: 5693 | C325: 2009 | D325: 2 | E325: 639.66667 | F325: NULL | G325: NULL | H325: NULL | I325: NULL | J325: 221133.68
... A416: 15/9-F-4 | B416: 5693 | C416: 2016 | D416: 9 | E416: 340.10833 | F416: NULL | G416: NULL | H416: NULL | I416: NULL | J416: 61200.876
A417: 15/9-F-4 | B417: 5693 | C417: 2016 | D417: 10 | E417: NULL | F417: NULL | G417: NULL | H417: NULL | I417: NULL | J417: NULL
A418: 15/9-F-4 | B418: 5693 | C418: 2016 | D418: 11 | E418: NULL | F418: NULL | G418: NULL | H418: NULL | I418: NULL | J418: NULL
A419: 15/9-F-4 | B419: 5693 | C419: 2016 | D419: 12 | E419: NULL | F419: NULL | G419: NULL | H419: NULL | I419: NULL | J419: NULL
A420: 15/9-F-5 | B420: 5769 | C420: 2007 | D420: 9 | E420: NULL | F420: NULL | G420: NULL | H420: NULL | I420: NULL | J420: NULL
A421: 15/9-F-5 | B421: 5769 | C421: 2007 | D421: 10 | E421: NULL | F421: NULL | G421: NULL | H421: NULL | I421: NULL | J421: NULL
A422: 15/9-F-5 | B422: 5769 | C422: 2007 | D422: 11 | E422: NULL | F422: NULL | G422: NULL | H422: NULL | I422: NULL | J422: NULL
...

Sheet Roles
A1: Wellbore name | B1: Role
A2: 15/9-F-1 C | B2: Producer
A3: 15/9-F-11 H | B3: Producer
A4: 15/9-F-12 H | B4: Producer
A5: 15/9-F-14 H | B5: Producer
A6: 15/9-F-15 D | B6: Producer
A7: 15/9-F-4 AH | B7: Injector
A8: 15/9-F-5 AH | B8: Injector
